<?xml version="1.0" ?>
<robot name="mbot">

    <link name="base_link">
        <visual>
            <origin xyz="0 0 0" rpy="0 0 0" />
            <geometry>
                <mesh filename="package://mbot_description/meshes/base_link.dae" />
            </geometry>
        </visual>
    </link>

	<!-- Caster base and Caster wheel -->
	<link name="caster_base">
        <visual>
            <origin xyz=" 0 0 0" rpy="0 0 0" />
            <geometry>
                <mesh filename="package://mbot_description/meshes/caster_base2.dae" />
            </geometry>
        </visual>
    </link>

	<joint name="caster_base_joint" type="continuous">
        <origin xyz="-0.20 0.0 -0.03033" rpy="0 0 0"/>
        <parent link="base_link"/>
        <child link="caster_base"/>
        <axis xyz="0 0 1" rpy="0 0 0"/>
    </joint>

	<link name="caswheel">
        <visual>
            <origin xyz=" 0 0 0" rpy="1.57 0 0" />
            <geometry>
                <mesh filename="package://mbot_description/meshes/caswheel.dae" />
            </geometry>
        </visual>
    </link>
	
	<joint name="caswheel_caster_joint" type="continuous">
		<origin xyz="-0.02626 0.0 -0.042385" rpy="0 0 0"/>
        <parent link="caster_base"/>
        <child link="caswheel"/>
        <axis xyz="0 1 0" rpy="0 0 0"/>
    </joint>

	<!-- left wheel -->
	<link name="left_wheel_link">
        <visual>
            <origin xyz=" 0 0 0" rpy="0 0 1.57" />
            <geometry>
                <mesh filename="package://mbot_description/meshes/wheel.dae" />
            </geometry>
        </visual>
    </link>

	<joint name="left_wheel_joint" type="continuous">
		<origin xyz="-0.04 0.14 -0.045" rpy="0 0 0" />
        <parent link="base_link"/>
        <child link="left_wheel_link"/>
        <axis xyz="0 1 0" rpy="0 0 0"/>
    </joint>

	<!-- right wheel -->
	<link name="right_wheel_link">
        <visual>
            <origin xyz=" 0 0 0" rpy="0 0 1.57" />
            <geometry>
                <mesh filename="package://mbot_description/meshes/wheel.dae" />
            </geometry>
        </visual>
    </link>

	<joint name="right_wheel_joint" type="continuous">
		 <origin xyz="-0.04 -0.14 -0.045" rpy="0 0 0" />
        <parent link="base_link"/>
        <child link="right_wheel_link"/>
        <axis xyz="0 1 0" rpy="0 0 0"/>
    </joint>
	
	<!-- kinect sensor -->
	<link name="kinect_link">
        <visual>
            <origin xyz="0 0 0" rpy="0 0 1.57"/>
            <geometry>
                <mesh filename="package://mbot_description/meshes/kinect.dae" />
            </geometry>
        </visual>
    </link>

    <joint name="kinect_joint" type="fixed">
        <origin xyz="-0.2 0 0.037" rpy="0 0 3.14"/>
        <parent link="base_link"/>
        <child link="kinect_link"/>
    </joint>
    
</robot>
