<?xml version="1.0" ?>
<robot name="kk_robot">
<!--  base 测试 -->
    <link name="base_link">
        <visual>
            <geometry>
                <box size="0.5 0.5 0.1"/>
            </geometry>
            <material name="white">
                <color rgba="1 1 1 1"/>
            </material>
            <origin xyz="0 0 0" rpy="0 0 0"/>
        </visual>
    </link>
    <!--  upper_base_link  -->
    <link name="upper_base_link">
        <visual>
            <geometry>
                <box size="0.5 0.5 0.1"/>
            </geometry>
            <material name="white">
                <color rgba="1 1 1 1"/>
            </material>
            <origin xyz="0 0 0" rpy="0 0 0"/>
        </visual>
    </link>

    <!--  base and upper base joint;fixed  -->
    <joint name="base_upper_base_joint" type="fixed">
        <parent link="base_link"/>
        <child link="upper_base_link"/>
        <origin xyz="0 0 0.3" rpy="0 0 0"/>
    </joint>
    <!--  fl_support_link  -->
    <link name="fl_support_link">
        <visual>
            <geometry>
                <box size="0.05 0.05 0.3"/>
            </geometry>
            <material name="black">
                <color rgba="0 0 0 1"/>
            </material>
            <origin xyz="0 0 0.15" rpy="0 0 0"/>
        </visual>
    </link>
    <!--  base and fl support joint;fixed  -->
    <joint name="base_fl_support_joint" type="fixed">
        <parent link="base_link"/>
        <child link="fl_support_link"/>
        <origin xyz="0.2 0.2 0" rpy="0 0 0"/>
    </joint>
    <!--  fr_support_link  -->
    <link name="fr_support_link">
        <visual>
            <geometry>
                <box size="0.05 0.05 0.3"/>
            </geometry>
            <material name="black">
                <color rgba="0 0 0 1"/>
            </material>
            <origin xyz="0 0 0.15" rpy="0 0 0"/>
        </visual>
    </link>
    <!--  base and fr support joint;fixed  -->
    <joint name="base_fr_support_joint" type="fixed">
        <parent link="base_link"/>
        <child link="fr_support_link"/>
        <origin xyz="0.2 -0.2 0" rpy="0 0 0"/>
    </joint>
    <!--  rf_support_link  -->
    <link name="rf_support_link">
        <visual>
            <geometry>
                <box size="0.05 0.05 0.3"/>
            </geometry>
            <material name="black">
                <color rgba="0 0 0 1"/>
            </material>
            <origin xyz="0 0 0.15" rpy="0 0 0"/>
        </visual>
    </link>
    <!--  base and rf support joint;fixed  -->
    <joint name="base_rf_support_joint" type="fixed">
        <parent link="base_link"/>
        <child link="rf_support_link"/>
        <origin xyz="-0.2 0.2 0" rpy="0 0 0"/>
    </joint>
    <!--  rr_support_link  -->
    <link name="rr_support_link">
        <visual>
            <geometry>
                <box size="0.05 0.05 0.3"/>
            </geometry>
            <material name="black">
                <color rgba="0 0 0 1"/>
            </material>
            <origin xyz="0 0 0.15" rpy="0 0 0"/>
        </visual>
    </link>
    <!--  base and rr support joint;fixed  -->
    <joint name="base_rr_support_joint" type="fixed">
        <parent link="base_link"/>
        <child link="rr_support_link"/>
        <origin xyz="-0.2 -0.2 0" rpy="0 0 0"/>
    </joint>
    <!--  kinect_link  -->
    <link name="kinect_link">
        <visual>
            <geometry>
                <mesh filename="package://kbot_description/meshes/kinect.dae"/>
            </geometry>
            <origin xyz="0 0 0" rpy="0 0 1.5708"/>
        </visual>
    </link>
    <!--  upper base and kinect joint;fixed  -->
    <joint name="upper_base_kinect_joint" type="fixed">
        <parent link="upper_base_link"/>
        <child link="kinect_link"/>
        <origin xyz="0.2 0 0.08" rpy="0 0 0"/>
    </joint>
    <!--  lidar base  -->
    <link name="lidar_base_link">
        <visual>
            <geometry>
                <box size="0.1 0.1 0.1"/>
            </geometry>
            <material name="white">
                <color rgba="1 1 1 1"/>
            </material>
            <origin xyz="0 0 0.05" rpy="0 0 0"/>
        </visual>
    </link>
    <!--  upper base and lidar base joint;fixed  -->
    <joint name="upper_base_lidar_base_joint" type="fixed">
        <parent link="upper_base_link"/>
        <child link="lidar_base_link"/>
        <origin xyz="0 0 0" rpy="0 0 0"/>
    </joint>
    <!--  lidar  -->
    <link name="lidar_link">
        <visual>
            <geometry>
                <cylinder length="0.08" radius="0.05"/>
            </geometry>
            <material name="black">
                <color rgba="0 0 0 1"/>
            </material>
            <origin xyz="0 0 0.04" rpy="0 0 0"/>
        </visual>
    </link>
    <!--  lidar base and lidar joint;fixed  -->
    <joint name="base_lidar_lidar_joint" type="fixed">
        <parent link="lidar_base_link"/>
        <child link="lidar_link"/>
        <origin xyz="0 0 0.05" rpy="0 0 0"/>
    </joint>
    <!--  real axle  -->
    <link name="rear_axle_link">
        <visual>
            <geometry>
                <cylinder length="0.54" radius="0.04"/>
            </geometry>
            <material name="white">
                <color rgba="1 1 1 1"/>
            </material>
            <origin xyz="0 0 0" rpy="1.5707 0 0"/>
        </visual>
    </link>
    <!--  base and rear axle joint;fixed  -->
    <joint name="base_rear_axle_joint" type="fixed">
        <parent link="base_link"/>
        <child link="rear_axle_link"/>
        <origin xyz="-0.2 0 0" rpy="0 0 0"/>
    </joint>
    <!--  rr wheel  -->
    <link name="rr_wheel_link">
        <visual>
            <geometry>
                <cylinder length="0.08" radius="0.12"/>
            </geometry>
            <material name="red">
                <color rgba="1 0 0 0.9"/>
            </material>
            <origin xyz="0 -0.04 0" rpy="1.5707 0 0"/>
        </visual>
    </link>
    <!--  rear axle and rr wheel joint;continuous  -->
    <joint name="base_rr_while_joint" type="continuous">
        <origin xyz="0 -0.27 0" rpy="0 0 0"/>
        <parent link="rear_axle_link"/>
        <child link="rr_wheel_link"/>
        <axis xyz="0 1 0"/>
    </joint>
    <!--  rl wheel  -->
    <link name="rl_wheel_link">
        <visual>
            <geometry>
                <cylinder length="0.08" radius="0.12"/>
            </geometry>
            <material name="blue">
                <color rgba="0 0 1 0.9"/>
            </material>
            <origin xyz="0 0.04 0" rpy="1.5707 0 0"/>
        </visual>
    </link>
    <!--  rear axle and rl wheel joint;continuous  -->
    <joint name="base_rl_while_joint" type="continuous">
        <origin xyz="0 0.27 0" rpy="0 0 0"/>
        <parent link="rear_axle_link"/>
        <child link="rl_wheel_link"/>
        <axis xyz="0 1 0"/>
    </joint>
    <!--  font wheel  -->
    <link name="font_wheel_link">
        <visual>
            <geometry>
                <cylinder length="0.08" radius="0.12"/>
            </geometry>
            <material name="green">
                <color rgba="0 1 0 0.9"/>
            </material>
            <origin xyz="0 0 0" rpy="1.5707 0 0"/>
        </visual>
    </link>
    <!--  base and font wheel joint;revolute  -->
    <joint name="base_font_while_joint" type="revolute">
        <origin xyz="0.21 0 0" rpy="0 0 0"/>
        <parent link="base_link"/>
        <child link="font_wheel_link"/>
        <axis xyz="0 0 1"/>
        <limit lower="-0.5236" upper="0.5236" effort="1.0" velocity="1.0"/>
    </joint>
</robot>
