<?xml version="1.0" ?>
<robot name="mbot">
	<link name="base_link">
		<visual>
 			<origin xyz=" 0 0 0" rpy="0 0 0" />
            		<geometry>
                		<box size="0.25 0.25 0.1" />
            		</geometry>
            		<material name="yellow">
                		<color rgba="1 0.4 0 1"/>
            		</material>
		</visual>
	</link>
        
	<joint name="front_left_wheel_joint" type="continuous">
		<origin xyz="0.075 0.125 -0.05" rpy="0 0 0"/>
        	<parent link="base_link"/>
        	<child link="front_left_wheel_link"/>
        	<axis xyz="0 1 0"/>
    	</joint>

    	<link name="front_left_wheel_link">
        	<visual>
            		<origin xyz="0 0 0" rpy="1.5707 0 0" />
            		<geometry>
                		<cylinder radius="0.05" length = "0.025"/>
            		</geometry>
            		<material name="white">
                		<color rgba="1 1 1 0.9"/>
            		</material>
        	</visual>
    	</link>

	<joint name="front_right_wheel_joint" type="continuous">
		<origin xyz="0.075 -0.125 -0.05" rpy="0 0 0"/>
        	<parent link="base_link"/>
        	<child link="front_right_wheel_link"/>
        	<axis xyz="0 1 0"/>
    	</joint>

    	<link name="front_right_wheel_link">
        	<visual>
            		<origin xyz="0 0 0" rpy="1.5707 0 0" />
            		<geometry>
                		<cylinder radius="0.05" length = "0.025"/>
            		</geometry>
            		<material name="white">
                		<color rgba="1 1 1 0.9"/>
            		</material>
        	</visual>
    	</link>
	
	<joint name="back_left_wheel_joint" type="continuous">
		<origin xyz="-0.075 0.125 -0.05" rpy="0 0 0"/>
        	<parent link="base_link"/>
        	<child link="back_left_wheel_link"/>
        	<axis xyz="0 1 0"/>
    	</joint>

    	<link name="back_left_wheel_link">
        	<visual>
            		<origin xyz="0 0 0" rpy="1.5707 0 0" />
            		<geometry>
                		<cylinder radius="0.05" length = "0.025"/>
            		</geometry>
            		<material name="white">
                		<color rgba="1 1 1 0.9"/>
            		</material>
        	</visual>
    	</link>

	<joint name="back_right_wheel_joint" type="continuous">
		<origin xyz="-0.075 -0.125 -0.05" rpy="0 0 0"/>
        	<parent link="base_link"/>
        	<child link="back_right_wheel_link"/>
        	<axis xyz="0 1 0"/>
    	</joint>

    	<link name="back_right_wheel_link">
        	<visual>
            		<origin xyz="0 0 0" rpy="1.5707 0 0" />
            		<geometry>
                		<cylinder radius="0.05" length = "0.025"/>
            		</geometry>
            		<material name="white">
                		<color rgba="1 1 1 0.9"/>
            		</material>
        	</visual>
    	</link>

	<joint name="kinect_joint" type="revolute">
        	<origin xyz="0.07 0 0.08" rpy="0 0 0"/>
        	<parent link="base_link"/>
        	<child link="kinect_link"/>
		<axis xyz="0 0 1"/>
		<limit effort="30" velocity="1.0" lower="-0.7" upper="0.7" />
    	</joint>
	
	<link name="kinect_link">
	        <visual>
        	    <origin xyz="0 0 0" rpy="0 0 1.5708"/>
	            <geometry>
        	        <mesh filename="package://mbot_description/meshes/kinect.dae" />
        	    </geometry>
        	</visual>
    	</link>

</robot>
